<mujoco model="go2">
  <compiler angle="radian" meshdir="assets" autolimits="true" />

  <option cone="elliptic" impratio="1" />

  <visual>
    <global offheight="2160" offwidth="3840"/>
    <quality offsamples="8"/>
  </visual>

  <default>
    <default class="go2">
      <geom friction="0.4" margin="0.001" condim="1"/>
      <camera fovy="58"/>
      <joint axis="0 1 0" armature="0.01" />
      <position kp="25" kv="3.0" inheritrange="1.5" timeconst="0.06" />
      
      <default class="abduction">
        <joint axis="1 0 0" range="-1.0472 1.0472" frictionloss="0.3"/>

      </default>
      <default class="hip">
        <default class="front_hip">
          <joint range="-1.5708 3.4907" frictionloss="0.3"/>
        </default>
        <default class="back_hip">
          <joint range="-0.5236 4.5379" frictionloss="0.3"/>
        </default>
      </default>
      <default class="knee">
        <joint range="-2.7227 -0.83776" frictionloss="0.5"/>
      </default>
      <default class="visual">
        <geom type="mesh" contype="0" conaffinity="0" group="2"/>
      </default>
      <default class="collision">
        <geom group="3"/>
        <default class="foot">
          <geom size="0.022" pos="-0.002 0 -0.213" priority="1" condim="6"
            friction="0.8 0.7 0.7"/>
        </default>
      </default>
    </default>
  </default>

  <asset>
    <material name="metal" rgba=".9 .95 .95 1" />
    <material name="black" rgba="0 0 0 1" />
    <material name="white" rgba="1 1 1 1" />
    <material name="gray" rgba="0.671705 0.692426 0.774270 1" />

    <mesh file="base_0.obj" />
    <mesh file="base_1.obj" />
    <mesh file="base_2.obj" />
    <mesh file="base_3.obj" />
    <mesh file="base_4.obj" />
    <!-- <mesh file="mounts_test.obj" /> -->
    <mesh file="hip_0.obj" />
    <mesh file="hip_1.obj" />
    <mesh file="thigh_0.obj" />
    <mesh file="thigh_1.obj" />
    <mesh file="thigh_mirror_0.obj" />
    <mesh file="thigh_mirror_1.obj" />
    <mesh file="calf_0.obj" />
    <mesh file="calf_1.obj" />
    <mesh file="calf_mirror_0.obj" />
    <mesh file="calf_mirror_1.obj" />
    <mesh file="foot.obj" />
  </asset>

  <worldbody>
    <body name="base_link" pos="0 0 0.445" childclass="go2">
      <inertial pos="0.021112 0 -0.005366" quat="-0.000543471 0.713435 -0.00173769 0.700719"
        mass="6.921"
        diaginertia="0.107027 0.0980771 0.0244531" />
      <freejoint />
      <geom mesh="base_0" material="black" class="visual" />
      <geom mesh="base_1" material="black" class="visual" />
      <geom mesh="base_2" material="black" class="visual" />
      <geom mesh="base_3" material="white" class="visual" />
      <geom mesh="base_4" material="gray" class="visual" />
      <!-- <geom mesh="mounts_test" material="black" class="visual" /> -->
      <geom name="base_box" size="0.075 0.0881" pos="0.0 0 0.01" quat="0 0.7071 0 0.7071" type="capsule" class="collision" />
      <geom name="base_head_top" size="0.045 0.027" pos="0.285 0 0.01" type="capsule" class="collision" />
      <geom name="base_head_bottom" size="0.047" pos="0.293 0 -0.06" class="collision" />

      <site name="imu" pos="-0.02557 0 0.04232" />
      <site name="base_site" pos="0 0 0" />

      <geom name="z_dummy" pos="0 0 0" size="0.001" />


      <camera name="front" pos="0.33 0 0.105" quat="0.56098553 0.43045933 -0.43045933 -0.56098553"/>
      <site name="front_cam" pos="0.33 0 0.105" quat="0.56098553 0.43045933 -0.43045933 -0.56098553"/>
      <camera name="top" pos="0.265 0 0.105" quat="0 1 0 0" />
      <site name="top_cam" pos="0.265 0 0.105" quat="0 1 0 0" />
      <camera name="back" pos="-0.118 0 0.105" quat="0.56098553 0.43045933 0.43045933 0.56098553"/>
      <site name="back_cam" pos="-0.118 0 0.105" quat="0.56098553 0.43045933 0.43045933 0.56098553"/>
      <camera name="bottom" pos="0.12 0 -0.085"/>
      <site name="bottom_cam" pos="0.12 0 -0.085"/>
      
      <site name="FL_hip_fixed_site" pos="0.1934 0.142 0" />
      <body name="FL_hip" pos="0.1934 0.0465 0">
        <inertial pos="-0.0054 0.00194 -0.000105" quat="0.497014 0.499245 0.505462 0.498237"
          mass="0.678"
          diaginertia="0.00088403 0.000596003 0.000479967" />
        <joint name="FL_hip_joint" class="abduction" />
        <geom mesh="hip_0" material="metal" class="visual" />
        <geom mesh="hip_1" material="gray" class="visual" />
        <geom name="FL_hip_geom" size="0.046" pos="0 0.08 0" quat="0.707107 0.707107 0 0" type="sphere" class="collision" />
        <body name="FL_thigh" pos="0 0.0955 0">
          <inertial pos="-0.00374 -0.0223 -0.0327" quat="0.829533 0.0847635 -0.0200632 0.551623"
            mass="1.152"
            diaginertia="0.00594973 0.00584149 0.000878787" />
          <site name="FL_thigh_site" pos="0 0 0" />
          <joint name="FL_thigh_joint" class="front_hip" />
          <geom mesh="thigh_0" material="metal" class="visual" />
          <geom mesh="thigh_1" material="gray" class="visual" />
          <geom name="FL_thigh_geom" size="0.017 0.1015" pos="0 0 -0.1065" quat="0 0.707107 0.707107 0"
            type="capsule" class="collision" />
          <body name="FL_calf" pos="0 0 -0.213">
            <inertial pos="0.00629595 -0.000622121 -0.141417"
              quat="0.710672 0.00154099 -0.00450087 0.703508"
              mass="0.241352" diaginertia="0.0014901 0.00146356 5.31397e-05" />
            <joint name="FL_calf_joint" class="knee" />
            <geom mesh="calf_0" material="gray" class="visual" />
            <geom mesh="calf_1" material="black" class="visual" />
            <geom name="FL_shank_top" size="0.013 0.055" pos="0.01 0 -0.06" quat="0.994493 0 -0.104807 0"
              type="capsule" class="collision" />
            <geom name="FL_shank_bottom" size="0.013 0.044" pos="0.018 0 -0.148" quat="0.999688 0 0.0249974 0"
              type="capsule" class="collision" />
            <geom pos="0 0 -0.213" mesh="foot" class="visual" material="black" />
            <geom name="FL" class="foot" />
            <body name="FL_foot" pos="0 0 -0.213" />
            <site name="FL_foot_site" pos="0 0 -0.213" size="0.024"/>
          </body>
        </body>
      </body>
      <site name="FR_hip_fixed_site" pos="0.1934 -.142 0" />
      <body name="FR_hip" pos="0.1934 -0.0465 0">
        <inertial pos="-0.0054 -0.00194 -0.000105" quat="0.498237 0.505462 0.499245 0.497014"
          mass="0.678"
          diaginertia="0.00088403 0.000596003 0.000479967" />
        <joint name="FR_hip_joint" class="abduction" />
        <geom mesh="hip_0" material="metal" class="visual" quat="4.63268e-05 1 0 0" />
        <geom mesh="hip_1" material="gray" class="visual" quat="4.63268e-05 1 0 0" />
        <geom name="FR_hip_geom" size="0.046" pos="0 -0.08 0" quat="0.707107 0.707107 0 0" type="sphere"
          class="collision" />
        <geom name="FR_hip_dummy" size="0.01" pos="0 -0.08 0" />
        <body name="FR_thigh" pos="0 -0.0955 0">
          <inertial pos="-0.00374 0.0223 -0.0327" quat="0.551623 -0.0200632 0.0847635 0.829533"
            mass="1.152"
            diaginertia="0.00594973 0.00584149 0.000878787" />
          <site name="FR_thigh_site" pos="0 0 0" />
          <joint name="FR_thigh_joint" class="front_hip" />
          <geom mesh="thigh_mirror_0" material="metal" class="visual" />
          <geom mesh="thigh_mirror_1" material="gray" class="visual" />
          <geom name="FR_thigh_geom" size="0.017 0.1015" pos="0 0 -0.1065" quat="0 0.707107 0.707107 0"
            type="capsule" class="collision"  />
          <body name="FR_calf" pos="0 0 -0.213">
            <inertial pos="0.00629595 0.000622121 -0.141417"
              quat="0.703508 -0.00450087 0.00154099 0.710672"
              mass="0.241352" diaginertia="0.0014901 0.00146356 5.31397e-05" />
            <joint name="FR_calf_joint" class="knee" />
            <geom mesh="calf_mirror_0" material="gray" class="visual" />
            <geom mesh="calf_mirror_1" material="black" class="visual" />
            <geom name="FR_shank_top" size="0.013 0.055" pos="0.01 0 -0.06" quat="0.995004 0 -0.0998334 0"
              type="capsule" class="collision" />
            <geom name="FR_shank_bottom" size="0.013 0.044" pos="0.018 0 -0.148" quat="0.999688 0 0.0249974 0"
              type="capsule" class="collision" />
            <geom pos="0 0 -0.213" mesh="foot" class="visual" material="black" />
            <geom name="FR" class="foot" />
            <body name="FR_foot" pos="0 0 -0.213" />
            <site name="FR_foot_site" pos="0 0 -0.213" size="0.024"/>
          </body>
        </body>
      </body>
      <site name="RL_hip_fixed_site" pos="-0.1934 0.142 0" />
      <body name="RL_hip" pos="-0.1934 0.0465 0">
        <inertial pos="0.0054 0.00194 -0.000105" quat="0.505462 0.498237 0.497014 0.499245"
          mass="0.678"
          diaginertia="0.00088403 0.000596003 0.000479967" />
        <joint name="RL_hip_joint" class="abduction" />
        <geom mesh="hip_0" material="metal" class="visual" quat="4.63268e-05 0 1 0" />
        <geom mesh="hip_1" material="gray" class="visual" quat="4.63268e-05 0 1 0" />
        <geom name="RL_hip_geom" size="0.046" pos="0 0.08 0" quat="0.707107 0.707107 0 0" type="sphere"
          class="collision" />
        <geom name="RL_hip_dummy" size="0.01" pos="0 0.08 0" />
        <body name="RL_thigh" pos="0 0.0955 0">
          <inertial pos="-0.00374 -0.0223 -0.0327" quat="0.829533 0.0847635 -0.0200632 0.551623"
            mass="1.152"
            diaginertia="0.00594973 0.00584149 0.000878787" />
          <site name="RL_thigh_site" pos="0 0 0" />
          <joint name="RL_thigh_joint" class="back_hip" />
          <geom mesh="thigh_0" material="metal" class="visual" />
          <geom mesh="thigh_1" material="gray" class="visual" />
          <geom name="RL_thigh_geom" size="0.017 0.1015" pos="0 0 -0.1065" quat="0 0.707107 0.707107 0"
            type="capsule" class="collision" />
          <body name="RL_calf" pos="0 0 -0.213">
            <inertial pos="0.00629595 -0.000622121 -0.141417"
              quat="0.710672 0.00154099 -0.00450087 0.703508"
              mass="0.241352" diaginertia="0.0014901 0.00146356 5.31397e-05" />
            <joint name="RL_calf_joint" class="knee" />
            <geom mesh="calf_0" material="gray" class="visual" />
            <geom mesh="calf_1" material="black" class="visual" />
            <geom name="RL_shank_top" size="0.013 0.055" pos="0.01 0 -0.06" quat="0.995004 0 -0.0998334 0"
              type="capsule" class="collision" />
            <geom name="RL_shank_bottom" size="0.013 0.044" pos="0.018 0 -0.148" quat="0.999688 0 0.0249974 0"
              type="capsule" class="collision" />
            <geom pos="0 0 -0.213" mesh="foot" class="visual" material="black" />
            <geom name="RL" class="foot" />
            <body name="RL_foot" pos="0 0 -0.213" />
            <site name="RL_foot_site" pos="0 0 -0.213" size="0.024"/>
          </body>
        </body>
      </body>
      <site name="RR_hip_fixed_site" pos="-0.1934 -.142 0" />
      <body name="RR_hip" pos="-0.1934 -0.0465 0">
        <inertial pos="0.0054 -0.00194 -0.000105" quat="0.499245 0.497014 0.498237 0.505462"
          mass="0.678"
          diaginertia="0.00088403 0.000596003 0.000479967" />
        <joint name="RR_hip_joint" class="abduction" />
        <geom mesh="hip_0" material="metal" class="visual"
          quat="2.14617e-09 4.63268e-05 4.63268e-05 -1" />
        <geom mesh="hip_1" material="gray" class="visual"
          quat="2.14617e-09 4.63268e-05 4.63268e-05 -1" />
        <geom name="RR_hip_geom" size="0.046" pos="0 -0.08 0" quat="0.707107 0.707107 0 0" type="sphere"
          class="collision" />
        <geom name="RR_hip_dummy" size="0.01" pos="0 -0.08 0" />
        <body name="RR_thigh" pos="0 -0.0955 0">
          <inertial pos="-0.00374 0.0223 -0.0327" quat="0.551623 -0.0200632 0.0847635 0.829533"
            mass="1.152"
            diaginertia="0.00594973 0.00584149 0.000878787" />
          <site name="RR_thigh_site" pos="0 0 0" />
          <joint name="RR_thigh_joint" class="back_hip" />
          <geom mesh="thigh_mirror_0" material="metal" class="visual" />
          <geom mesh="thigh_mirror_1" material="gray" class="visual" />
          <geom name="RR_thigh_geom" size="0.017 0.1015" pos="0 0 -0.1065" quat="0 0.707107 0.707107 0"
            type="capsule" class="collision"  />
          <body name="RR_calf" pos="0 0 -0.213">
            <inertial pos="0.00629595 0.000622121 -0.141417"
              quat="0.703508 -0.00450087 0.00154099 0.710672"
              mass="0.241352" diaginertia="0.0014901 0.00146356 5.31397e-05" />
            <joint name="RR_calf_joint" class="knee" />
            <geom mesh="calf_mirror_0" material="gray" class="visual" />
            <geom mesh="calf_mirror_1" material="black" class="visual" />
            <geom name="RR_shank_top" size="0.013 0.055" pos="0.01 0 -0.06" quat="0.995004 0 -0.0998334 0"
              type="capsule" class="collision" />
            <geom name="RR_shank_bottom" size="0.013 0.044" pos="0.018 0 -0.148" quat="0.999688 0 0.0249974 0"
              type="capsule" class="collision" />
            <geom pos="0 0 -0.213" mesh="foot" class="visual" material="black" />
            <geom name="RR" class="foot" />
            <body name="RR_foot" pos="0 0 -0.213" />
            <site name="RR_foot_site" pos="0 0 -0.213" size="0.024"/>
          </body>
        </body>
      </body>
    </body>
  </worldbody>

  <actuator>
    <position class="abduction" name="FL_hip_q" joint="FL_hip_joint" />
    <position class="hip" name="FL_thigh_q" joint="FL_thigh_joint" />
    <position class="knee" name="FL_calf_q" joint="FL_calf_joint" />
    <position class="abduction" name="FR_hip_q" joint="FR_hip_joint" />
    <position class="hip" name="FR_thigh_q" joint="FR_thigh_joint" />
    <position class="knee" name="FR_calf_q" joint="FR_calf_joint" />
    <position class="abduction" name="RL_hip_q" joint="RL_hip_joint" />
    <position class="hip" name="RL_thigh_q" joint="RL_thigh_joint" />
    <position class="knee" name="RL_calf_q" joint="RL_calf_joint" />
    <position class="abduction" name="RR_hip_q" joint="RR_hip_joint" />
    <position class="hip" name="RR_thigh_q" joint="RR_thigh_joint" />
    <position class="knee" name="RR_calf_q" joint="RR_calf_joint" />
  </actuator>

  <keyframe>
    <key name="home" qpos="0 0 0.27 1 0 0 0 0 0.9 -1.8 0 0.9 -1.8 0 0.9 -1.8 0 0.9 -1.8"
     ctrl="0 0.9 -1.8 0 0.9 -1.8 0 0.9 -1.8 0 0.9 -1.8" /> 
    <key name="init" qpos="0 0 0.4 1 0 0 0 0.1 0.8 -1.5 -0.1 0.8 -1.5 0.1 1.0 -1.5 -0.1 1.0 -1.5" />
  </keyframe>
</mujoco>